Workbook

Sheet 01_DASHBOARD
B1: CLASS CASH DASHBOARD
B2: JULY 26 CASH TROUGH
B3: Finance Baseline Trough | E3: Adjusted Scenario Trough | H3: Δ vs Baseline | K3: Weeks Below $500K
B4: =MIN('07_Weekly_Engine'!F5:F38) | E4: =MIN('07_Weekly_Engine'!N5:N38) | H4: =E4-B4 | K4: =COUNTIF('07_Weekly_Engine'!N5:N38,"<500000")
B5: Week #30 (July 26, 2026) | E5: Min ending cash across all weeks | H5: Positive = your levers help | K5: Lower = better
B7: WEEKLY CASH PATH — FINANCE BASELINE vs ADJUSTED SCENARIO
B26: HOW TO READ | C26: ━ ━ Baseline (Finance) — board-deck path with no cost actions | E26: ─── Adjusted — your levers applied (severance, cost cuts, bookings) | G26: ◆ Trough = lowest point of cash year
C27: ━ ━ Danger floor ($500K) — burn-out risk | E27: ━ ━ Target floor ($1.5M) — comfortable operating level | G27: Gap (navy − gold) = $ added by your levers
B28: SCENARIO SUMMARY — TROUGH & ENDING CASH
B29: Scenario | C29: July 26 Trough | D29: Δ vs Baseline | E29: Jan 3 Ending | F29: Heads Cut | G29: Total Severance | H29: Annual FL Savings
B30: Finance Baseline (= Board Deck) | C30: =MIN('07_Weekly_Engine'!F5:F38) | D30: =C30-C30 | E30: ='07_Weekly_Engine'!F38 | F30: — | G30: — | H30: —
B31: Your Adjusted Scenario | C31: =MIN('07_Weekly_Engine'!N5:N38) | D31: =C31-C30 | E31: ='07_Weekly_Engine'!N38 | F31: =COUNTIFS('02_Severance_Inputs'!I18:I45,"<>None",'02_Severance_Inputs'!I18:I45,"<>None (protected)") | G31: =SUM('02_Severance_Inputs'!M18:M45) | H31: =SUM('02_Severance_Inputs'!N18:N45)*52
B34: QUICK ACTIONS
B35: Edit who is cut and severance terms | C35: → Go to Severance Inputs
B36: Adjust AWS / software / line items | C36: → Go to Cost Levers
B37: Change new sales bookings projection | C37: → Go to Bookings Inputs
B38: See AWS detailed scenario modeling | C38: → Go to AWS Analysis
B39: See where Finance may be conservative | C39: → Go to NS Variance
B40: See full weekly calculation engine | C40: → Go to Weekly Engine
B43: OPEN QUESTIONS
B44: Ambiguous tranche assignments | C44: =COUNTIF('02_Severance_Inputs'!I18:I45,"None") | D44: employees with Tranche="None" — should be "None (protected)" or an actual tranche
B45: Bookings inflow active weeks | C45: =COUNTIF('07_Weekly_Engine'!L5:L38,">0") | D45: weeks have non-zero bookings — verify cadence matches expectation
B46: Cost Lever T1a Annual Adjustment | C46: ='03_Cost_Levers'!E16 | D46: T1a contribution (zero = lever defined but inactive)

Sheet 00_README
B1: CLASS TECHNOLOGIES — CASH LEVER MODEL v5
B2: How to Use This Workbook | May 18, 2026
B4: HOW THIS MODEL WORKS
B5: PURPOSE: Answer this single question — 'What levers, pulled in the next 6 weeks, change the July 26 cash trough?'
B7: STRUCTURE:
B8: • 01_DASHBOARD — the live view (cash chart, scenario summary, July headline)
B9: • 02_Severance_Inputs — per-person editor (one row per employee, ONE tranche assignment, severance weeks)
B10: • 03_Cost_Levers — adjust any Finance Baseline line item (AWS, software, etc.)
B11: • 04_Bookings_Inputs — model new sales bookings with 60-day cash conversion lag
B12: • 05_AWS_Analysis — deep dive on AWS costs, ICS savings, scenario modeling
B13: • 06_NS_Variance — NetSuite actuals vs Finance forecast (where Finance may be conservative)
B14: • 07_Weekly_Engine — calculation engine (formula-driven; do not edit unless debugging)
... B38: COLOR KEY
B39: Indicator | C39: Color | D39: Meaning
B40: Yellow tint (input) | D40: Cells you can edit — controls and assumptions
B41: Blue tint (calc) | D41: Computed cells — formulas; do not edit
B42: Navy header | D42: Column headers and titles
B43: Green | D43: Positive / favorable outcomes
B44: Amber | D44: Warning / borderline
B45: Red | D45: Crisis / unfavorable / cannot complete by June 1

Sheet 02_Severance_Inputs
B1: EMPLOYEE SEVERANCE & TRANCHE ASSIGNMENT
B2: 41 employees | One tranche per person (no double-counting) | Yellow = editable
B4: # | C4: Employee | D4: Title | E4: Loc | F4: Base $ | G4: FL $ | H4: Dept | I4: Tranche | J4: Sev. Weeks | K4: Mode | L4: Term Date | M4: Severance $ | N4: Wkly Saving | O4: Sev End Week | P4: Savings Start Wk | Q4: Cash Impact in July? | R4: July Impact $
B5: 7 | C5: Ed Miller | D5: SVP Business Dev & Strategy | E5: US | F5: 250000 | G5: 400000 | H5: Sales | I5: T1 | J5: 12 | K5: Spread | L5: 46387 | M5: =IF(J5=0,0,F5*J5/52) | N5: =IF(OR(I5="None",I5="None (protected)"),0,G5/52) | O5: =IF(OR(K5="Spread",K5="spread"),ROUNDUP(J5/5,0),IF(K5="Czech-Notice",22,0)) | P5: =O5+1 | Q5: =IF(OR(I5="None",I5="None (protected)"),"N/A",IF(K5="Czech-Notice","No (Czech notice runs to Oct)",IF(J5<=5,"YES — helps July",IF(J5<=8,"Partial — late July only","No — paid through mid-Aug+")))) | R5: =IF(OR(I5="None",I5="None (protected)"),0,IF(K5="Czech-Notice",0,IF(K5="Lump",4*N5-M5,MAX(0,(11-O5))*N5)))
B6: 9 | C6: Massimo Gentili | D6: Head of EMEA | E6: EU | F6: 135931 | G6: 409431 | H6: Sales | I6: T1 | J6: 12 | K6: Spread | L6: 46387 | M6: =IF(J6=0,0,F6*J6/52) | N6: =IF(OR(I6="None",I6="None (protected)"),0,G6/52) | O6: =IF(OR(K6="Spread",K6="spread"),ROUNDUP(J6/5,0),IF(K6="Czech-Notice",22,0)) | P6: =O6+1 | Q6: =IF(OR(I6="None",I6="None (protected)"),"N/A",IF(K6="Czech-Notice","No (Czech notice runs to Oct)",IF(J6<=5,"YES — helps July",IF(J6<=8,"Partial — late July only","No — paid through mid-Aug+")))) | R6: =IF(OR(I6="None",I6="None (protected)"),0,IF(K6="Czech-Notice",0,IF(K6="Lump",4*N6-M6,MAX(0,(11-O6))*N6)))
B7: 13 | C7: Roxana Nabavian | D7: Marketing | E7: US | F7: 79920 | G7: 99900 | H7: Marketing | I7: T1 | J7: 6 | K7: Spread | L7: 46173 | M7: =IF(J7=0,0,F7*J7/52) | N7: =IF(OR(I7="None",I7="None (protected)"),0,G7/52) | O7: =IF(OR(K7="Spread",K7="spread"),ROUNDUP(J7/5,0),IF(K7="Czech-Notice",22,0)) | P7: =O7+1 | Q7: =IF(OR(I7="None",I7="None (protected)"),"N/A",IF(K7="Czech-Notice","No (Czech notice runs to Oct)",IF(J7<=5,"YES — helps July",IF(J7<=8,"Partial — late July only","No — paid through mid-Aug+")))) | R7: =IF(OR(I7="None",I7="None (protected)"),0,IF(K7="Czech-Notice",0,IF(K7="Lump",4*N7-M7,MAX(0,(11-O7))*N7)))
B8: 10 | C8: Clayton Coyne | D8: Dir, Partnerships & Channel | E8: US | F8: 145000 | G8: 221625 | H8: Sales | I8: T1 | J8: 6 | K8: Spread | L8: 46173 | M8: =IF(J8=0,0,F8*J8/52) | N8: =IF(OR(I8="None",I8="None (protected)"),0,G8/52) | O8: =IF(OR(K8="Spread",K8="spread"),ROUNDUP(J8/5,0),IF(K8="Czech-Notice",22,0)) | P8: =O8+1 | Q8: =IF(OR(I8="None",I8="None (protected)"),"N/A",IF(K8="Czech-Notice","No (Czech notice runs to Oct)",IF(J8<=5,"YES — helps July",IF(J8<=8,"Partial — late July only","No — paid through mid-Aug+")))) | R8: =IF(OR(I8="None",I8="None (protected)"),0,IF(K8="Czech-Notice",0,IF(K8="Lump",4*N8-M8,MAX(0,(11-O8))*N8)))
B9: 27 | C9: Michal Marek | D9: Staff SE | E9: CZ | F9: 79384 | G9: 130983 | H9: Product | I9: T2 | J9: 4 | K9: Czech-Notice | L9: 46173 | M9: =IF(J9=0,0,F9*J9/52) | N9: =IF(OR(I9="None",I9="None (protected)"),0,G9/52) | O9: =IF(OR(K9="Spread",K9="spread"),ROUNDUP(J9/5,0),IF(K9="Czech-Notice",22,0)) | P9: =O9+1 | Q9: =IF(OR(I9="None",I9="None (protected)"),"N/A",IF(K9="Czech-Notice","No (Czech notice runs to Oct)",IF(J9<=5,"YES — helps July",IF(J9<=8,"Partial — late July only","No — paid through mid-Aug+")))) | R9: =IF(OR(I9="None",I9="None (protected)"),0,IF(K9="Czech-Notice",0,IF(K9="Lump",4*N9-M9,MAX(0,(11-O9))*N9)))
B10: 28 | C10: Bronek Gabrhelik | D10: Staff SE | E10: CZ | F10: 78164 | G10: 128971 | H10: Product | I10: T2 | J10: 4 | K10: Czech-Notice | L10: 46173 | M10: =IF(J10=0,0,F10*J10/52) | N10: =IF(OR(I10="None",I10="None (protected)"),0,G10/52) | O10: =IF(OR(K10="Spread",K10="spread"),ROUNDUP(J10/5,0),IF(K10="Czech-Notice",22,0)) | P10: =O10+1 | Q10: =IF(OR(I10="None",I10="None (protected)"),"N/A",IF(K10="Czech-Notice","No (Czech notice runs to Oct)",IF(J10<=5,"YES — helps July",IF(J10<=8,"Partial — late July only","No — paid through mid-Aug+")))) | R10: =IF(OR(I10="None",I10="None (protected)"),0,IF(K10="Czech-Notice",0,IF(K10="Lump",4*N10-M10,MAX(0,(11-O10))*N10)))
B11: 30 | C11: Pavel Mican | D11: Staff SE | E11: CZ | F11: 61598 | G11: 101638 | H11: Product | I11: T2 | J11: 4 | K11: Czech-Notice | L11: 46173 | M11: =IF(J11=0,0,F11*J11/52) | N11: =IF(OR(I11="None",I11="None (protected)"),0,G11/52) | O11: =IF(OR(K11="Spread",K11="spread"),ROUNDUP(J11/5,0),IF(K11="Czech-Notice",22,0)) | P11: =O11+1 | Q11: =IF(OR(I11="None",I11="None (protected)"),"N/A",IF(K11="Czech-Notice","No (Czech notice runs to Oct)",IF(J11<=5,"YES — helps July",IF(J11<=8,"Partial — late July only","No — paid through mid-Aug+")))) | R11: =IF(OR(I11="None",I11="None (protected)"),0,IF(K11="Czech-Notice",0,IF(K11="Lump",4*N11-M11,MAX(0,(11-O11))*N11)))
B12: 32 | C12: Jakub Samek | D12: Sr SE | E12: CZ | F12: 50202 | G12: 75303 | H12: Product | I12: T2 | J12: 4 | K12: Czech-Notice | L12: 46173 | M12: =IF(J12=0,0,F12*J12/52) | N12: =IF(OR(I12="None",I12="None (protected)"),0,G12/52) | O12: =IF(OR(K12="Spread",K12="spread"),ROUNDUP(J12/5,0),IF(K12="Czech-Notice",22,0)) | P12: =O12+1 | Q12: =IF(OR(I12="None",I12="None (protected)"),"N/A",IF(K12="Czech-Notice","No (Czech notice runs to Oct)",IF(J12<=5,"YES — helps July",IF(J12<=8,"Partial — late July only","No — paid through mid-Aug+")))) | R12: =IF(OR(I12="None",I12="None (protected)"),0,IF(K12="Czech-Notice",0,IF(K12="Lump",4*N12-M12,MAX(0,(11-O12))*N12)))
B13: 36 | C13: Roksolana Bondarenko | D13: QA Engineer | E13: CZ | F13: 36522 | G13: 54783 | H13: Product | I13: T2 | J13: 4 | K13: Czech-Notice | L13: 46173 | M13: =IF(J13=0,0,F13*J13/52) | N13: =IF(OR(I13="None",I13="None (protected)"),0,G13/52) | O13: =IF(OR(K13="Spread",K13="spread"),ROUNDUP(J13/5,0),IF(K13="Czech-Notice",22,0)) | P13: =O13+1 | Q13: =IF(OR(I13="None",I13="None (protected)"),"N/A",IF(K13="Czech-Notice","No (Czech notice runs to Oct)",IF(J13<=5,"YES — helps July",IF(J13<=8,"Partial — late July only","No — paid through mid-Aug+")))) | R13: =IF(OR(I13="None",I13="None (protected)"),0,IF(K13="Czech-Notice",0,IF(K13="Lump",4*N13-M13,MAX(0,(11-O13))*N13)))
B14: 5 | C14: Andy Prescott | D14: Director Rev Accounting | E14: US | F14: 180000 | G14: 224850 | H14: G&A | I14: T3 | J14: 6 | K14: Spread | L14: 46295 | M14: =IF(J14=0,0,F14*J14/52) | N14: =IF(OR(I14="None",I14="None (protected)"),0,G14/52) | O14: =IF(OR(K14="Spread",K14="spread"),ROUNDUP(J14/5,0),IF(K14="Czech-Notice",22,0)) | P14: =O14+1 | Q14: =IF(OR(I14="None",I14="None (protected)"),"N/A",IF(K14="Czech-Notice","No (Czech notice runs to Oct)",IF(J14<=5,"YES — helps July",IF(J14<=8,"Partial — late July only","No — paid through mid-Aug+")))) | R14: =IF(OR(I14="None",I14="None (protected)"),0,IF(K14="Czech-Notice",0,IF(K14="Lump",4*N14-M14,MAX(0,(11-O14))*N14)))
B15: 6 | C15: Kyle Delaney | D15: Revenue Manager | E15: US | F15: 120000 | G15: 146375 | H15: G&A | I15: T3 | J15: 6 | K15: Spread | L15: 46295 | M15: =IF(J15=0,0,F15*J15/52) | N15: =IF(OR(I15="None",I15="None (protected)"),0,G15/52) | O15: =IF(OR(K15="Spread",K15="spread"),ROUNDUP(J15/5,0),IF(K15="Czech-Notice",22,0)) | P15: =O15+1 | Q15: =IF(OR(I15="None",I15="None (protected)"),"N/A",IF(K15="Czech-Notice","No (Czech notice runs to Oct)",IF(J15<=5,"YES — helps July",IF(J15<=8,"Partial — late July only","No — paid through mid-Aug+")))) | R15: =IF(OR(I15="None",I15="None (protected)"),0,IF(K15="Czech-Notice",0,IF(K15="Lump",4*N15-M15,MAX(0,(11-O15))*N15)))
B16: 22 | C16: Monica González | D16: Impl Mgr & SE | E16: MX | F16: 76274 | G16: 91274 | H16: CS | I16: T3 | J16: 6 | K16: Spread | L16: 46295 | M16: =IF(J16=0,0,F16*J16/52) | N16: =IF(OR(I16="None",I16="None (protected)"),0,G16/52) | O16: =IF(OR(K16="Spread",K16="spread"),ROUNDUP(J16/5,0),IF(K16="Czech-Notice",22,0)) | P16: =O16+1 | Q16: =IF(OR(I16="None",I16="None (protected)"),"N/A",IF(K16="Czech-Notice","No (Czech notice runs to Oct)",IF(J16<=5,"YES — helps July",IF(J16<=8,"Partial — late July only","No — paid through mid-Aug+")))) | R16: =IF(OR(I16="None",I16="None (protected)"),0,IF(K16="Czech-Notice",0,IF(K16="Lump",4*N16-M16,MAX(0,(11-O16))*N16)))
... B19: 12 | C19: Dalton Mullins | D19: SDR | E19: US | F19: 50000 | G19: 93000 | H19: Marketing | I19: None | J19: 6 | K19: Spread | L19: 46387 | M19: =IF(J19=0,0,F19*J19/52) | N19: =IF(OR(I19="None",I19="None (protected)"),0,G19/52) | O19: =IF(OR(K19="Spread",K19="spread"),ROUNDUP(J19/5,0),IF(K19="Czech-Notice",22,0)) | P19: =O19+1 | Q19: =IF(OR(I19="None",I19="None (protected)"),"N/A",IF(K19="Czech-Notice","No (Czech notice runs to Oct)",IF(J19<=5,"YES — helps July",IF(J19<=8,"Partial — late July only","No — paid through mid-Aug+")))) | R19: =IF(OR(I19="None",I19="None (protected)"),0,IF(K19="Czech-Notice",0,IF(K19="Lump",4*N19-M19,MAX(0,(11-O19))*N19)))
B20: 40 | C20: AJ Gorton | D20: Commercial Sales Manager | E20: US | F20: 120000 | G20: 302250 | H20: CoSo | I20: None | J20: 6 | K20: Spread | L20: — | M20: =IF(J20=0,0,F20*J20/52) | N20: =IF(OR(I20="None",I20="None (protected)"),0,G20/52) | O20: =IF(OR(K20="Spread",K20="spread"),ROUNDUP(J20/5,0),IF(K20="Czech-Notice",22,0)) | P20: =O20+1 | Q20: =IF(OR(I20="None",I20="None (protected)"),"N/A",IF(K20="Czech-Notice","No (Czech notice runs to Oct)",IF(J20<=5,"YES — helps July",IF(J20<=8,"Partial — late July only","No — paid through mid-Aug+")))) | R20: =IF(OR(I20="None",I20="None (protected)"),0,IF(K20="Czech-Notice",0,IF(K20="Lump",4*N20-M20,MAX(0,(11-O20))*N20)))
B21: 8 | C21: Daniel Hansen | D21: Director of Sales | E21: US | F21: 160000 | G21: 380750 | H21: Sales | I21: None | J21: 6 | K21: Spread | L21: 46173 | M21: =IF(J21=0,0,F21*J21/52) | N21: =IF(OR(I21="None",I21="None (protected)"),0,G21/52) | O21: =IF(OR(K21="Spread",K21="spread"),ROUNDUP(J21/5,0),IF(K21="Czech-Notice",22,0)) | P21: =O21+1 | Q21: =IF(OR(I21="None",I21="None (protected)"),"N/A",IF(K21="Czech-Notice","No (Czech notice runs to Oct)",IF(J21<=5,"YES — helps July",IF(J21<=8,"Partial — late July only","No — paid through mid-Aug+")))) | R21: =IF(OR(I21="None",I21="None (protected)"),0,IF(K21="Czech-Notice",0,IF(K21="Lump",4*N21-M21,MAX(0,(11-O21))*N21)))
B22: 29 | C22: Ivo Novosad | D22: Sr Mgr SE | E22: CZ | F22: 67654 | G22: 111629 | H22: Product | I22: None | J22: 6 | K22: Czech-Notice | M22: =IF(J22=0,0,F22*J22/52) | N22: =IF(OR(I22="None",I22="None (protected)"),0,G22/52) | O22: =IF(OR(K22="Spread",K22="spread"),ROUNDUP(J22/5,0),IF(K22="Czech-Notice",22,0)) | P22: =O22+1 | Q22: =IF(OR(I22="None",I22="None (protected)"),"N/A",IF(K22="Czech-Notice","No (Czech notice runs to Oct)",IF(J22<=5,"YES — helps July",IF(J22<=8,"Partial — late July only","No — paid through mid-Aug+")))) | R22: =IF(OR(I22="None",I22="None (protected)"),0,IF(K22="Czech-Notice",0,IF(K22="Lump",4*N22-M22,MAX(0,(11-O22))*N22)))
B23: 31 | C23: Robin Wolny | D23: Sr DevOps | E23: CZ | F23: 58310 | G23: 87464 | H23: Product | I23: None | J23: 6 | K23: Czech-Notice | M23: =IF(J23=0,0,F23*J23/52) | N23: =IF(OR(I23="None",I23="None (protected)"),0,G23/52) | O23: =IF(OR(K23="Spread",K23="spread"),ROUNDUP(J23/5,0),IF(K23="Czech-Notice",22,0)) | P23: =O23+1 | Q23: =IF(OR(I23="None",I23="None (protected)"),"N/A",IF(K23="Czech-Notice","No (Czech notice runs to Oct)",IF(J23<=5,"YES — helps July",IF(J23<=8,"Partial — late July only","No — paid through mid-Aug+")))) | R23: =IF(OR(I23="None",I23="None (protected)"),0,IF(K23="Czech-Notice",0,IF(K23="Lump",4*N23-M23,MAX(0,(11-O23))*N23)))
B24: 33 | C24: Marek Odraska | D24: Sr Test Auto | E24: CZ | F24: 47987 | G24: 71981 | H24: Product | I24: None | J24: 6 | K24: Czech-Notice | M24: =IF(J24=0,0,F24*J24/52) | N24: =IF(OR(I24="None",I24="None (protected)"),0,G24/52) | O24: =IF(OR(K24="Spread",K24="spread"),ROUNDUP(J24/5,0),IF(K24="Czech-Notice",22,0)) | P24: =O24+1 | Q24: =IF(OR(I24="None",I24="None (protected)"),"N/A",IF(K24="Czech-Notice","No (Czech notice runs to Oct)",IF(J24<=5,"YES — helps July",IF(J24<=8,"Partial — late July only","No — paid through mid-Aug+")))) | R24: =IF(OR(I24="None",I24="None (protected)"),0,IF(K24="Czech-Notice",0,IF(K24="Lump",4*N24-M24,MAX(0,(11-O24))*N24)))
B25: 34 | C25: Jiri Stefek | D25: Sr Test Auto | E25: CZ | F25: 44224 | G25: 66336 | H25: Product | I25: None | J25: 6 | K25: Czech-Notice | M25: =IF(J25=0,0,F25*J25/52) | N25: =IF(OR(I25="None",I25="None (protected)"),0,G25/52) | O25: =IF(OR(K25="Spread",K25="spread"),ROUNDUP(J25/5,0),IF(K25="Czech-Notice",22,0)) | P25: =O25+1 | Q25: =IF(OR(I25="None",I25="None (protected)"),"N/A",IF(K25="Czech-Notice","No (Czech notice runs to Oct)",IF(J25<=5,"YES — helps July",IF(J25<=8,"Partial — late July only","No — paid through mid-Aug+")))) | R25: =IF(OR(I25="None",I25="None (protected)"),0,IF(K25="Czech-Notice",0,IF(K25="Lump",4*N25-M25,MAX(0,(11-O25))*N25)))
B26: 37 | C26: Jan Mátl | D26: Full Stack Dev | E26: CZ | F26: 31304 | G26: 46957 | H26: Product | I26: None | J26: 6 | K26: Czech-Notice | M26: =IF(J26=0,0,F26*J26/52) | N26: =IF(OR(I26="None",I26="None (protected)"),0,G26/52) | O26: =IF(OR(K26="Spread",K26="spread"),ROUNDUP(J26/5,0),IF(K26="Czech-Notice",22,0)) | P26: =O26+1 | Q26: =IF(OR(I26="None",I26="None (protected)"),"N/A",IF(K26="Czech-Notice","No (Czech notice runs to Oct)",IF(J26<=5,"YES — helps July",IF(J26<=8,"Partial — late July only","No — paid through mid-Aug+")))) | R26: =IF(OR(I26="None",I26="None (protected)"),0,IF(K26="Czech-Notice",0,IF(K26="Lump",4*N26-M26,MAX(0,(11-O26))*N26)))
B27: 35 | C27: Abhinav Khawarey | D27: Product Manager | E27: IN | F27: 41137 | G27: 60437 | H27: Product | I27: None | J27: 0 | K27: N/A | L27: — | M27: =IF(J27=0,0,F27*J27/52) | N27: =IF(OR(I27="None",I27="None (protected)"),0,G27/52) | O27: =IF(OR(K27="Spread",K27="spread"),ROUNDUP(J27/5,0),IF(K27="Czech-Notice",22,0)) | P27: =O27+1 | Q27: =IF(OR(I27="None",I27="None (protected)"),"N/A",IF(K27="Czech-Notice","No (Czech notice runs to Oct)",IF(J27<=5,"YES — helps July",IF(J27<=8,"Partial — late July only","No — paid through mid-Aug+")))) | R27: =IF(OR(I27="None",I27="None (protected)"),0,IF(K27="Czech-Notice",0,IF(K27="Lump",4*N27-M27,MAX(0,(11-O27))*N27)))
B28: 1 | C28: Michael Chasen | D28: CEO | E28: US | F28: 250000 | G28: 400000 | H28: G&A | I28: None | J28: 0 | K28: N/A | L28: — | M28: =IF(J28=0,0,F28*J28/52) | N28: =IF(OR(I28="None",I28="None (protected)"),0,G28/52) | O28: =IF(OR(K28="Spread",K28="spread"),ROUNDUP(J28/5,0),IF(K28="Czech-Notice",22,0)) | P28: =O28+1 | Q28: =IF(OR(I28="None",I28="None (protected)"),"N/A",IF(K28="Czech-Notice","No (Czech notice runs to Oct)",IF(J28<=5,"YES — helps July",IF(J28<=8,"Partial — late July only","No — paid through mid-Aug+")))) | R28: =IF(OR(I28="None",I28="None (protected)"),0,IF(K28="Czech-Notice",0,IF(K28="Lump",4*N28-M28,MAX(0,(11-O28))*N28)))
B29: 2 | C29: Brian Bharwani | D29: CFO | E29: US | F29: 250000 | G29: 400000 | H29: G&A | I29: None | J29: 0 | K29: N/A | L29: — | M29: =IF(J29=0,0,F29*J29/52) | N29: =IF(OR(I29="None",I29="None (protected)"),0,G29/52) | O29: =IF(OR(K29="Spread",K29="spread"),ROUNDUP(J29/5,0),IF(K29="Czech-Notice",22,0)) | P29: =O29+1 | Q29: =IF(OR(I29="None",I29="None (protected)"),"N/A",IF(K29="Czech-Notice","No (Czech notice runs to Oct)",IF(J29<=5,"YES — helps July",IF(J29<=8,"Partial — late July only","No — paid through mid-Aug+")))) | R29: =IF(OR(I29="None",I29="None (protected)"),0,IF(K29="Czech-Notice",0,IF(K29="Lump",4*N29-M29,MAX(0,(11-O29))*N29)))
B30: 3 | C30: Russell Teter | D30: SVP BD & Ops | E30: US | F30: 250000 | G30: 400000 | H30: G&A | I30: None | J30: 0 | K30: N/A | L30: — | M30: =IF(J30=0,0,F30*J30/52) | N30: =IF(OR(I30="None",I30="None (protected)"),0,G30/52) | O30: =IF(OR(K30="Spread",K30="spread"),ROUNDUP(J30/5,0),IF(K30="Czech-Notice",22,0)) | P30: =O30+1 | Q30: =IF(OR(I30="None",I30="None (protected)"),"N/A",IF(K30="Czech-Notice","No (Czech notice runs to Oct)",IF(J30<=5,"YES — helps July",IF(J30<=8,"Partial — late July only","No — paid through mid-Aug+")))) | R30: =IF(OR(I30="None",I30="None (protected)"),0,IF(K30="Czech-Notice",0,IF(K30="Lump",4*N30-M30,MAX(0,(11-O30))*N30)))
B31: 4 | C31: Nicole Brantley | D31: VP of Accounting | E31: US | F31: 205000 | G31: 276450 | H31: G&A | I31: None | J31: 0 | K31: N/A | L31: — | M31: =IF(J31=0,0,F31*J31/52) | N31: =IF(OR(I31="None",I31="None (protected)"),0,G31/52) | O31: =IF(OR(K31="Spread",K31="spread"),ROUNDUP(J31/5,0),IF(K31="Czech-Notice",22,0)) | P31: =O31+1 | Q31: =IF(OR(I31="None",I31="None (protected)"),"N/A",IF(K31="Czech-Notice","No (Czech notice runs to Oct)",IF(J31<=5,"YES — helps July",IF(J31<=8,"Partial — late July only","No — paid through mid-Aug+")))) | R31: =IF(OR(I31="None",I31="None (protected)"),0,IF(K31="Czech-Notice",0,IF(K31="Lump",4*N31-M31,MAX(0,(11-O31))*N31)))
B32: 14 | C32: Sabina Cramer | D32: SVP Renewal Sales | E32: EU | F32: 223220 | G32: 409431 | H32: Renewals | I32: None | J32: 0 | K32: N/A | L32: — | M32: =IF(J32=0,0,F32*J32/52) | N32: =IF(OR(I32="None",I32="None (protected)"),0,G32/52) | O32: =IF(OR(K32="Spread",K32="spread"),ROUNDUP(J32/5,0),IF(K32="Czech-Notice",22,0)) | P32: =O32+1 | Q32: =IF(OR(I32="None",I32="None (protected)"),"N/A",IF(K32="Czech-Notice","No (Czech notice runs to Oct)",IF(J32<=5,"YES — helps July",IF(J32<=8,"Partial — late July only","No — paid through mid-Aug+")))) | R32: =IF(OR(I32="None",I32="None (protected)"),0,IF(K32="Czech-Notice",0,IF(K32="Lump",4*N32-M32,MAX(0,(11-O32))*N32)))
B33: 15 | C33: Andee Bodenstein | D33: Account Manager NA | E33: US | F33: 115000 | G33: 178625 | H33: Renewals | I33: None | J33: 0 | K33: N/A | L33: — | M33: =IF(J33=0,0,F33*J33/52) | N33: =IF(OR(I33="None",I33="None (protected)"),0,G33/52) | O33: =IF(OR(K33="Spread",K33="spread"),ROUNDUP(J33/5,0),IF(K33="Czech-Notice",22,0)) | P33: =O33+1 | Q33: =IF(OR(I33="None",I33="None (protected)"),"N/A",IF(K33="Czech-Notice","No (Czech notice runs to Oct)",IF(J33<=5,"YES — helps July",IF(J33<=8,"Partial — late July only","No — paid through mid-Aug+")))) | R33: =IF(OR(I33="None",I33="None (protected)"),0,IF(K33="Czech-Notice",0,IF(K33="Lump",4*N33-M33,MAX(0,(11-O33))*N33)))
B34: 16 | C34: Holly Hardin | D34: CS Manager | E34: US | F34: 110000 | G34: 142075 | H34: Renewals | I34: None | J34: 0 | K34: N/A | L34: — | M34: =IF(J34=0,0,F34*J34/52) | N34: =IF(OR(I34="None",I34="None (protected)"),0,G34/52) | O34: =IF(OR(K34="Spread",K34="spread"),ROUNDUP(J34/5,0),IF(K34="Czech-Notice",22,0)) | P34: =O34+1 | Q34: =IF(OR(I34="None",I34="None (protected)"),"N/A",IF(K34="Czech-Notice","No (Czech notice runs to Oct)",IF(J34<=5,"YES — helps July",IF(J34<=8,"Partial — late July only","No — paid through mid-Aug+")))) | R34: =IF(OR(I34="None",I34="None (protected)"),0,IF(K34="Czech-Notice",0,IF(K34="Lump",4*N34-M34,MAX(0,(11-O34))*N34)))
B35: 17 | C35: Robert Thayer | D35: Account Manager | E35: US | F35: 104000 | G35: 156050 | H35: Renewals | I35: None | J35: 0 | K35: N/A | L35: — | M35: =IF(J35=0,0,F35*J35/52) | N35: =IF(OR(I35="None",I35="None (protected)"),0,G35/52) | O35: =IF(OR(K35="Spread",K35="spread"),ROUNDUP(J35/5,0),IF(K35="Czech-Notice",22,0)) | P35: =O35+1 | Q35: =IF(OR(I35="None",I35="None (protected)"),"N/A",IF(K35="Czech-Notice","No (Czech notice runs to Oct)",IF(J35<=5,"YES — helps July",IF(J35<=8,"Partial — late July only","No — paid through mid-Aug+")))) | R35: =IF(OR(I35="None",I35="None (protected)"),0,IF(K35="Czech-Notice",0,IF(K35="Lump",4*N35-M35,MAX(0,(11-O35))*N35)))
B36: 18 | C36: Emmanuel Clemot | D36: Channel AM MENA | E36: EU | F36: 103150 | G36: 133150 | H36: Renewals | I36: None | J36: 0 | K36: N/A | L36: — | M36: =IF(J36=0,0,F36*J36/52) | N36: =IF(OR(I36="None",I36="None (protected)"),0,G36/52) | O36: =IF(OR(K36="Spread",K36="spread"),ROUNDUP(J36/5,0),IF(K36="Czech-Notice",22,0)) | P36: =O36+1 | Q36: =IF(OR(I36="None",I36="None (protected)"),"N/A",IF(K36="Czech-Notice","No (Czech notice runs to Oct)",IF(J36<=5,"YES — helps July",IF(J36<=8,"Partial — late July only","No — paid through mid-Aug+")))) | R36: =IF(OR(I36="None",I36="None (protected)"),0,IF(K36="Czech-Notice",0,IF(K36="Lump",4*N36-M36,MAX(0,(11-O36))*N36)))
B37: 19 | C37: Armanda Sereikaitė | D37: AM/CSM LAC | E37: Intl | F37: 65000 | G37: 80000 | H37: Renewals | I37: None | J37: 0 | K37: N/A | L37: — | M37: =IF(J37=0,0,F37*J37/52) | N37: =IF(OR(I37="None",I37="None (protected)"),0,G37/52) | O37: =IF(OR(K37="Spread",K37="spread"),ROUNDUP(J37/5,0),IF(K37="Czech-Notice",22,0)) | P37: =O37+1 | Q37: =IF(OR(I37="None",I37="None (protected)"),"N/A",IF(K37="Czech-Notice","No (Czech notice runs to Oct)",IF(J37<=5,"YES — helps July",IF(J37<=8,"Partial — late July only","No — paid through mid-Aug+")))) | R37: =IF(OR(I37="None",I37="None (protected)"),0,IF(K37="Czech-Notice",0,IF(K37="Lump",4*N37-M37,MAX(0,(11-O37))*N37)))
B38: 20 | C38: Jorge Salinas | D38: Dir Global SE | E38: US | F38: 151670 | G38: 191170 | H38: CS | I38: None | J38: 0 | K38: N/A | L38: — | M38: =IF(J38=0,0,F38*J38/52) | N38: =IF(OR(I38="None",I38="None (protected)"),0,G38/52) | O38: =IF(OR(K38="Spread",K38="spread"),ROUNDUP(J38/5,0),IF(K38="Czech-Notice",22,0)) | P38: =O38+1 | Q38: =IF(OR(I38="None",I38="None (protected)"),"N/A",IF(K38="Czech-Notice","No (Czech notice runs to Oct)",IF(J38<=5,"YES — helps July",IF(J38<=8,"Partial — late July only","No — paid through mid-Aug+")))) | R38: =IF(OR(I38="None",I38="None (protected)"),0,IF(K38="Czech-Notice",0,IF(K38="Lump",4*N38-M38,MAX(0,(11-O38))*N38)))
... B45: 39 | C45: Timma Wilson | D45: Client Support Engineer | E45: US | F45: 81557 | G45: 99674 | H45: Support | I45: None | J45: 0 | K45: N/A | L45: — | M45: =IF(J45=0,0,F45*J45/52) | N45: =IF(OR(I45="None",I45="None (protected)"),0,G45/52) | O45: =IF(OR(K45="Spread",K45="spread"),ROUNDUP(J45/5,0),IF(K45="Czech-Notice",22,0)) | P45: =O45+1 | Q45: =IF(OR(I45="None",I45="None (protected)"),"N/A",IF(K45="Czech-Notice","No (Czech notice runs to Oct)",IF(J45<=5,"YES — helps July",IF(J45<=8,"Partial — late July only","No — paid through mid-Aug+")))) | R45: =IF(OR(I45="None",I45="None (protected)"),0,IF(K45="Czech-Notice",0,IF(K45="Lump",4*N45-M45,MAX(0,(11-O45))*N45)))
C48: TOTALS BY TRANCHE
C49: T1 | D49: =COUNTIF(I5:I45,"T1") | M49: =SUMIF(I5:I45,"T1",M5:M45) | N49: =SUMIF(I5:I45,"T1",N5:N45)*52 | R49: =SUMIF(I5:I45,"T1",R5:R45)
C50: T2 | D50: =COUNTIF(I6:I46,"T1") | M50: =SUMIF(I5:I45,"T2",M5:M45) | N50: =SUMIF(I5:I45,"T2",N5:N45)*52 | R50: =SUMIF(I5:I45,"T2",R5:R45)
C51: T3 | D51: =COUNTIF(I7:I47,"T1") | M51: =SUMIF(I5:I45,"T3",M5:M45) | N51: =SUMIF(I5:I45,"T3",N5:N45)*52 | R51: =SUMIF(I5:I45,"T3",R5:R45)
...

Sheet 03_Cost_Levers
B1: COST LINE ITEM LEVERS
B2: Override Finance Forecast by Category | Yellow = editable | Positive adj = additional cash inflow
B4: Line Item | C4: Finance Forecast (34 wks) | D4: Monthly Avg | E4: Annual Adjustment | F4: Adjusted Total | G4: Weekly Impact | H4: Notes / Rationale
B5: AWS Fees | C5: -2484728 | D5: =C5/7.85 | E5: 0 | F5: =C5+E5 | G5: =E5/34 | H5: See 05_AWS_Analysis for detailed scenario modeling
B6: Zoom / Microsoft / OpenLMS | C6: -2495302 | D6: =C6/7.85 | E6: 0 | F6: =C6+E6 | G6: =E6/34 | H6: Vendor renegotiation; Zoom-to-ICS migration savings beyond AWS
B7: Software Subscriptions | C7: -626469 | D7: =C7/7.85 | E7: 0 | F7: =C7+E7 | G7: =E7/34 | H7: Subscription audit / cancellations / consolidation
B8: Legal Fees & Settlements | C8: -298000 | D8: =C8/7.85 | E8: 0 | F8: =C8+E8 | G8: =E8/34 | H8: Settlement timing; reduce engagement scope
B9: Agency Contractors | C9: -905589 | D9: =C9/7.85 | E9: 0 | F9: =C9+E9 | G9: =E9/34 | H9: Pause non-essential contractors
B10: Marketing Programs | C10: -148000 | D10: =C10/7.85 | E10: 0 | F10: =C10+E10 | G10: =E10/34 | H10: Pause non-essential marketing (already $4K/wk)
B11: Class/Collaborate Collections | C11: 8050000 | D11: =C11/7.85 | E11: 0 | F11: =C11+E11 | G11: =E11/34 | H11: AR acceleration — push Anthology, faster invoicing
B12: BME Collections | C12: 1750000 | D12: =C12/7.85 | E12: 0 | F12: =C12+E12 | G12: =E12/34 | H12: BME Saudi old AR collection efforts ($1.4M overdue from 2022-23)
B13: Blackboard Collections | C13: 2860000 | D13: =C13/7.85 | E13: 0 | F13: =C13+E13 | G13: =E13/34 | H13: Channel collection timing
B14: CoSo TSA Collections | C14: 1700000 | D14: =C14/7.85 | E14: 0 | F14: =C14+E14 | G14: =E14/34 | H14: Knox TSA payments — pulled forward?
B16: TOTAL ADJUSTMENT (weekly impact applied to baseline) | E16: =SUM(E5:E14) | G16: =SUM(G5:G14)
B19: HOW THIS WORKS
B20: 1. Finance Forecast column = the 34-week (W20-W53) total from the Finance Cash Flow Model May 10 snapshot.
B21: 2. Enter your adjustment in the Annual Adjustment column (POSITIVE numbers = additional cash benefit).
B22: 3. Example: if you think AWS will come in $300K under Finance forecast, enter +300000 → spread over 34 weeks (~$8,800/wk benefit).
B23: 4. Example: if AR acceleration pulls $500K of Class collections forward by 30 days, enter +500000 → adds ~$15K/wk to inflows.
B24: 5. The Weekly Engine sheet uses this total to adjust the cash path week-by-week.
B25: 6. For AWS specifically: see 05_AWS_Analysis for a structured scenario model — copy the desired result back to E5.
B26: 7. For NetSuite variance analysis (where Finance may be conservative): see 06_NS_Variance.

Sheet 04_Bookings_Inputs
B1: NEW SALES BOOKINGS — CASH CONVERSION
B2: Projection: $350K CoSo + $350K Class per quarter | 60-day lag to cash
B4: Period | C4: Bookings Type | D4: Annual Bookings $ | E4: Cash Arrival Period | F4: Cash to Forecast | G4: Notes
B5: Q2 2026 | C5: CoSo (Consulting) | D5: 350000 | E5: Late Aug - Mid Sep (W34-W36) | F5: July impact: $0 — too late to help trough
B6: Q2 2026 | C6: Class (New Logos) | D6: 350000 | E6: Late Aug - Mid Sep (W34-W36) | F6: July impact: $0 — too late to help trough
B7: Q3 2026 | C7: Combined CoSo + Class | D7: 700000 | E7: Late Nov - Mid Dec (W47-W49) | F7: Helps Q4 cash, not July
B8: Q4 2026 | C8: Combined CoSo + Class | D8: 700000 | E8: Feb-Mar 2027 (mostly outside forecast) | F8: Outside W53 forecast endpoint
B10: New sales bookings DO NOT help the July trough. Any deal closing now or in May/June will not collect for 30-60 days (best case). Q2 bookings close by June 30 → cash arrives August-September. Q1 bookings ALREADY closed are already in the Finance Baseline Class collections line. Only AR acceleration on EXISTING receivables could help July. See 03_Cost_Levers for that lever.

Sheet 05_AWS_Analysis
B1: AWS COST DEEP DIVE & SCENARIO MODELING
B2: Estimated breakdown + reduction levers | Source: Board deck + NS GL + assumptions
B4: KEY TAKEAWAY ON AWS
B5: Finance Forecast AWS at $258K-$317K/month for Jul-Sep is already pricing in the ICS migration savings (-$85K/mo). NS actuals show hosting still running $443K/month in April (pre-completion). May-June should show further reduction. ADDITIONAL AWS savings beyond Finance forecast are LIMITED to ~$23K-30K/month realistically achievable by mid-July (dev env shutoff + S3 lifecycle). This is real but modest — under $30K of July trough benefit. The AWS story is largely already in the baseline. AWS is not the silver bullet for July.
B7: COMPONENT BREAKDOWN — ESTIMATED
B8: Component | C8: Pre-ICS Run-Rate | D8: Post-ICS Run-Rate | E8: Monthly Savings | F8: Status | G8: Verification | H8: Notes
B9: Production Hosting — South America | C9: 14400 | D9: 0 | E9: 14400 | F9: Complete | G9: Board deck slide 14 | H9: Migrated to ICS
B10: Production Hosting — North America | C10: 38940 | D10: 11040 | E10: 27900 | F10: Complete | G10: Board deck slide 13 | H10: $930/day savings
B11: Production Hosting — Europe | C11: 58410 | D11: 15120 | E11: 43290 | F11: Complete | G11: Board deck slide 12 | H11: $1,443/day savings
B12: Subtotal ICS-related savings | C12: 111750 | D12: 26160 | E12: 85590 | F12: Realized | G12: Board deck | H12: ~$85K/mo run-rate savings
B14: Dev/Staging Environments | C14: 50000 | D14: 50000 | E14: 0 | F14: Stable | G14: Estimated | H14: Could reduce via auto-shutoff: -$15K/mo
B15: Data Transfer / Egress | C15: 30000 | D15: 30000 | E15: 0 | F15: Stable | G15: Estimated | H15: Could optimize: -$5-10K/mo
B16: Storage (S3, EBS) | C16: 30000 | D16: 30000 | E16: 0 | F16: Stable | G16: Estimated | H16: S3 lifecycle policy: -$5-10K/mo
B17: Other AWS Services | C17: 80000 | D17: 80000 | E17: 0 | F17: Stable | G17: Estimated | H17: Lambda, CF, etc
B18: Reserved Instance commitments | C18: 100000 | D18: 100000 | E18: 0 | F18: Locked | G18: Estimated | H18: Cannot reduce until expiry
B21: TOTAL AWS — ESTIMATED | C21: =C9+C10+C11+C14+C15+C16+C17+C18 | D21: =D9+D10+D11+D14+D15+D16+D17+D18 | E21: =C21-D21
B24: FINANCE FORECAST vs ESTIMATED REALITY
B25: Period | C25: Finance Forecast AWS | D25: NS Actual Hosting | E25: Variance | F25: Implied AWS Run-Rate
B26: Nov 2025 | C26: -421000 | D26: -509309 | E26: 88309 | F26: Pre-ICS
B27: Dec 2025 | C27: -388110 | D27: -519572 | E27: 131462 | F27: Pre-ICS
B28: Jan 2026 | C28: -317528 | D28: -414329 | E28: 96801 | F28: Migration started
B29: Feb 2026 | C29: -293786 | D29: -364210 | E29: 70424 | F29: Migration in progress
B30: Mar 2026 | C30: -258313 | D30: -427596 | E30: 169283 | F30: Migration in progress
B31: Apr 2026 | C31: -225946 | D31: -443401 | E31: 217455 | F31: ICS migration complete mid-April
B34: AWS SCENARIO MODELING — POTENTIAL ADDITIONAL SAVINGS
B35: Lever | C35: Estimated Monthly Savings | D35: Likelihood | E35: Implementation Time | F35: Cash Impact Through Jul 26
B36: Dev env auto-shutoff | C36: 15000 | D36: High | E36: 2-3 weeks | F36: $15K (1 month)
B37: S3 lifecycle policies (cold tiering) | C37: 8000 | D37: High | E37: 1-2 weeks | F37: $8K
B38: Reserved instance rightsizing audit | C38: 30000 | D38: Medium | E38: 6-8 weeks | F38: $0 (too slow for July)
B39: Spot instances for batch workloads | C39: 10000 | D39: Medium | E39: 4-6 weeks | F39: $0-5K
B40: Data transfer optimization | C40: 5000 | D40: Low | E40: 3-4 weeks | F40: $0-5K
B41: Negotiate volume discount | C41: 20000 | D41: Low-Med | E41: 8-12 weeks | F41: $0 (too slow)
B42: TOTAL realistic by mid-July | C42: 23000 | D42: Combined | E42: — | F42: $23K-30K July benefit

Sheet 06_NS_Variance
B1: NETSUITE ACTUALS vs FINANCE FORECAST — VARIANCE ANALYSIS
B2: Where the Finance Model may be over-forecasting expenses (potential July buffer)
B4: EXPENSE LINE-BY-LINE: NS L6M AVG vs FINANCE FORECAST RATE
B5: Category | C5: NS L6M Avg / Mo | D5: Finance Forecast Avg / Mo | E5: Variance / Mo | F5: Implied Buffer (May-Jul) | G5: Confidence | H5: Interpretation
B6: Hosting (AWS + Collaborate) | C6: -446405 | D6: -317528 | E6: -128878 | F6: -250000 | G6: High | H6: NS actuals HIGHER than Finance forecast → Finance optimistic; no buffer here
B7: Software Subscriptions (recent 3-mo) | C7: -163782 | D7: -195188 | E7: 31406 | F7: 75000 | G7: High | H7: NS recent runs lower than Finance avg → potential $75K buffer by July
B8: Salary Expense (recent 3-mo, ex bonus) | C8: -629937 | D8: -700000 | E8: 70063 | F8: 175000 | G8: Medium | H8: NS shows lower salary run-rate; partly timing, partly attrition
B9: External Consulting Fees | C9: -103690 | D9: -150000 | E9: 46310 | F9: 100000 | G9: Medium | H9: NS L6M trending down; April $44K vs avg $104K
B10: Outsourced Development | C10: -29463 | D10: -25000 | E10: -4463 | F10: -10000 | G10: High | H10: NS slightly above Finance; small variance
B11: Commissions | C11: -143862 | D11: -100000 | E11: -43862 | F11: -100000 | G11: High | H11: Higher than Finance projection — sales force still paid
B12: Conferences / Travel | C12: -10429 | D12: -20000 | E12: 9571 | F12: 25000 | G12: High | H12: Already minimal; small buffer
B13: Bank Charges | C13: -4441 | D13: -5000 | E13: 559 | F13: 1500 | G13: High | H13: Negligible
B14: Marketing/Ads | C14: -4748 | D14: -16000 | E14: 11252 | F14: 30000 | G14: High | H14: NS already very low; $30K possible buffer
B15: Reseller Commissions Amortization | C15: -175369 | D15: -200000 | E15: 24631 | F15: 60000 | G15: Medium | H15: Non-cash item; not relevant to cash forecast
B17: TOTAL POTENTIAL BUFFER (positive items only) | F17: =SUMIF(F6:F15,">0")
B20: TAKEAWAY — WHERE FINANCE MAY BE CONSERVATIVE
B21: BUFFER OPPORTUNITY (Finance forecast more conservative than NS actuals):
B22: • Software subscriptions: ~$75K potential buffer through July (NS trending below Finance)
B23: • Salary expense: ~$175K potential buffer (timing-related; partly due to recent departures)
B24: • External consulting: ~$100K (NS L6M trending down)
B25: • Marketing / Conferences / minor items: ~$50K combined
B26: • POTENTIAL TOTAL BUFFER through July: $400K-$500K — meaningful relief
B28: WHERE FINANCE MAY BE OPTIMISTIC (DOWNSIDE RISK):
B29: • Hosting (AWS+Collaborate): NS actuals -$129K/month HIGHER than Finance forecast
B30: • This $129K/month gap is consistent with ICS migration not yet fully reflected in NS actuals
B31: • If ICS savings come in slower than expected: -$200K-$300K worse than forecast through July
B33: NET REALISTIC BUFFER: $100K-$300K of expense forecast buffer that Finance may be carrying.
B34: This is material vs the $111K trough but not transformational. AR acceleration and one-time inflows remain the bigger levers.

Sheet 07_Weekly_Engine
B1: WEEKLY CALCULATION ENGINE
B2: Formula-driven • Pulls live from 02_Severance_Inputs, 03_Cost_Levers, 04_Bookings_Inputs • Do not edit calc cells
B4: Week | C4: Date | D4: Month | E4: Wk # | F4: Finance Net Flow | G4: Finance Ending Cash | H4: T1a Line Items | I4: T1 Tranche | J4: T2 Tranche | K4: T3 Tranche | L4: Bookings Inflow | M4: Total Adjustment | N4: Adj Net Flow | O4: Adj Ending Cash | P4: Status
B5: W20 | C5: 46159 | D5: May | E5: 1 | F5: -382634 | G5: 3258643 | H5: ='03_Cost_Levers'!$G$16 | I5: =SUMPRODUCT(($D$43:$D$83="T1")*($L$43:$L$83)*($E5>=$O$43:$O$83))-SUMPRODUCT(($D$43:$D$83="T1")*($M$43:$M$83)*($E5=$P$43:$P$83)) | J5: =SUMPRODUCT(($D$43:$D$83="T2")*($L$43:$L$83)*($E5>=$O$43:$O$83))-SUMPRODUCT(($D$43:$D$83="T2")*($M$43:$M$83)*($E5=$P$43:$P$83)) | K5: =SUMPRODUCT(($D$43:$D$83="T3")*($L$43:$L$83)*($E5>=$O$43:$O$83))-SUMPRODUCT(($D$43:$D$83="T3")*($M$43:$M$83)*($E5=$P$43:$P$83)) | L5: 0 | M5: =H5+I5+J5+K5+L5 | N5: =F5+M5 | O5: =3641277+N5 | P5: =IF(O5<500000,"⚠ Crisis (<$500K)",IF(O5<1000000,"Caution","OK"))
B6: W21 | C6: 46166 | D6: May | E6: 2 | F6: -1268371 | G6: 1990272 | H6: ='03_Cost_Levers'!$G$16 | I6: =SUMPRODUCT(($D$43:$D$83="T1")*($L$43:$L$83)*($E6>=$O$43:$O$83))-SUMPRODUCT(($D$43:$D$83="T1")*($M$43:$M$83)*($E6=$P$43:$P$83)) | J6: =SUMPRODUCT(($D$43:$D$83="T2")*($L$43:$L$83)*($E6>=$O$43:$O$83))-SUMPRODUCT(($D$43:$D$83="T2")*($M$43:$M$83)*($E6=$P$43:$P$83)) | K6: =SUMPRODUCT(($D$43:$D$83="T3")*($L$43:$L$83)*($E6>=$O$43:$O$83))-SUMPRODUCT(($D$43:$D$83="T3")*($M$43:$M$83)*($E6=$P$43:$P$83)) | L6: 0 | M6: =H6+I6+J6+K6+L6 | N6: =F6+M6 | O6: =O5+N6 | P6: =IF(O6<500000,"⚠ Crisis (<$500K)",IF(O6<1000000,"Caution","OK"))
B7: W22 | C7: 46173 | D7: May | E7: 3 | F7: 238020 | G7: 2228292 | H7: ='03_Cost_Levers'!$G$16 | I7: =SUMPRODUCT(($D$43:$D$83="T1")*($L$43:$L$83)*($E7>=$O$43:$O$83))-SUMPRODUCT(($D$43:$D$83="T1")*($M$43:$M$83)*($E7=$P$43:$P$83)) | J7: =SUMPRODUCT(($D$43:$D$83="T2")*($L$43:$L$83)*($E7>=$O$43:$O$83))-SUMPRODUCT(($D$43:$D$83="T2")*($M$43:$M$83)*($E7=$P$43:$P$83)) | K7: =SUMPRODUCT(($D$43:$D$83="T3")*($L$43:$L$83)*($E7>=$O$43:$O$83))-SUMPRODUCT(($D$43:$D$83="T3")*($M$43:$M$83)*($E7=$P$43:$P$83)) | L7: 0 | M7: =H7+I7+J7+K7+L7 | N7: =F7+M7 | O7: =O6+N7 | P7: =IF(O7<500000,"⚠ Crisis (<$500K)",IF(O7<1000000,"Caution","OK"))
B8: W23 | C8: 46180 | D8: Jun | E8: 4 | F8: -261722 | G8: 1966570 | H8: ='03_Cost_Levers'!$G$16 | I8: =SUMPRODUCT(($D$43:$D$83="T1")*($L$43:$L$83)*($E8>=$O$43:$O$83))-SUMPRODUCT(($D$43:$D$83="T1")*($M$43:$M$83)*($E8=$P$43:$P$83)) | J8: =SUMPRODUCT(($D$43:$D$83="T2")*($L$43:$L$83)*($E8>=$O$43:$O$83))-SUMPRODUCT(($D$43:$D$83="T2")*($M$43:$M$83)*($E8=$P$43:$P$83)) | K8: =SUMPRODUCT(($D$43:$D$83="T3")*($L$43:$L$83)*($E8>=$O$43:$O$83))-SUMPRODUCT(($D$43:$D$83="T3")*($M$43:$M$83)*($E8=$P$43:$P$83)) | L8: 0 | M8: =H8+I8+J8+K8+L8 | N8: =F8+M8 | O8: =O7+N8 | P8: =IF(O8<500000,"⚠ Crisis (<$500K)",IF(O8<1000000,"Caution","OK"))
B9: W24 | C9: 46187 | D9: Jun | E9: 5 | F9: -345296 | G9: 1621274 | H9: ='03_Cost_Levers'!$G$16 | I9: =SUMPRODUCT(($D$43:$D$83="T1")*($L$43:$L$83)*($E9>=$O$43:$O$83))-SUMPRODUCT(($D$43:$D$83="T1")*($M$43:$M$83)*($E9=$P$43:$P$83)) | J9: =SUMPRODUCT(($D$43:$D$83="T2")*($L$43:$L$83)*($E9>=$O$43:$O$83))-SUMPRODUCT(($D$43:$D$83="T2")*($M$43:$M$83)*($E9=$P$43:$P$83)) | K9: =SUMPRODUCT(($D$43:$D$83="T3")*($L$43:$L$83)*($E9>=$O$43:$O$83))-SUMPRODUCT(($D$43:$D$83="T3")*($M$43:$M$83)*($E9=$P$43:$P$83)) | L9: 0 | M9: =H9+I9+J9+K9+L9 | N9: =F9+M9 | O9: =O8+N9 | P9: =IF(O9<500000,"⚠ Crisis (<$500K)",IF(O9<1000000,"Caution","OK"))
B10: W25 | C10: 46194 | D10: Jun | E10: 6 | F10: -594958 | G10: 1026316 | H10: ='03_Cost_Levers'!$G$16 | I10: =SUMPRODUCT(($D$43:$D$83="T1")*($L$43:$L$83)*($E10>=$O$43:$O$83))-SUMPRODUCT(($D$43:$D$83="T1")*($M$43:$M$83)*($E10=$P$43:$P$83)) | J10: =SUMPRODUCT(($D$43:$D$83="T2")*($L$43:$L$83)*($E10>=$O$43:$O$83))-SUMPRODUCT(($D$43:$D$83="T2")*($M$43:$M$83)*($E10=$P$43:$P$83)) | K10: =SUMPRODUCT(($D$43:$D$83="T3")*($L$43:$L$83)*($E10>=$O$43:$O$83))-SUMPRODUCT(($D$43:$D$83="T3")*($M$43:$M$83)*($E10=$P$43:$P$83)) | L10: 0 | M10: =H10+I10+J10+K10+L10 | N10: =F10+M10 | O10: =O9+N10 | P10: =IF(O10<500000,"⚠ Crisis (<$500K)",IF(O10<1000000,"Caution","OK"))
B11: W26 | C11: 46201 | D11: Jun | E11: 7 | F11: 61739 | G11: 1088055 | H11: ='03_Cost_Levers'!$G$16 | I11: =SUMPRODUCT(($D$43:$D$83="T1")*($L$43:$L$83)*($E11>=$O$43:$O$83))-SUMPRODUCT(($D$43:$D$83="T1")*($M$43:$M$83)*($E11=$P$43:$P$83)) | J11: =SUMPRODUCT(($D$43:$D$83="T2")*($L$43:$L$83)*($E11>=$O$43:$O$83))-SUMPRODUCT(($D$43:$D$83="T2")*($M$43:$M$83)*($E11=$P$43:$P$83)) | K11: =SUMPRODUCT(($D$43:$D$83="T3")*($L$43:$L$83)*($E11>=$O$43:$O$83))-SUMPRODUCT(($D$43:$D$83="T3")*($M$43:$M$83)*($E11=$P$43:$P$83)) | L11: 0 | M11: =H11+I11+J11+K11+L11 | N11: =F11+M11 | O11: =O10+N11 | P11: =IF(O11<500000,"⚠ Crisis (<$500K)",IF(O11<1000000,"Caution","OK"))
B12: W27 | C12: 46208 | D12: Jul | E12: 8 | F12: -165221 | G12: 922834 | H12: ='03_Cost_Levers'!$G$16 | I12: =SUMPRODUCT(($D$43:$D$83="T1")*($L$43:$L$83)*($E12>=$O$43:$O$83))-SUMPRODUCT(($D$43:$D$83="T1")*($M$43:$M$83)*($E12=$P$43:$P$83)) | J12: =SUMPRODUCT(($D$43:$D$83="T2")*($L$43:$L$83)*($E12>=$O$43:$O$83))-SUMPRODUCT(($D$43:$D$83="T2")*($M$43:$M$83)*($E12=$P$43:$P$83)) | K12: =SUMPRODUCT(($D$43:$D$83="T3")*($L$43:$L$83)*($E12>=$O$43:$O$83))-SUMPRODUCT(($D$43:$D$83="T3")*($M$43:$M$83)*($E12=$P$43:$P$83)) | L12: 0 | M12: =H12+I12+J12+K12+L12 | N12: =F12+M12 | O12: =O11+N12 | P12: =IF(O12<500000,"⚠ Crisis (<$500K)",IF(O12<1000000,"Caution","OK"))
B13: W28 | C13: 46215 | D13: Jul | E13: 9 | F13: -109130 | G13: 813704 | H13: ='03_Cost_Levers'!$G$16 | I13: =SUMPRODUCT(($D$43:$D$83="T1")*($L$43:$L$83)*($E13>=$O$43:$O$83))-SUMPRODUCT(($D$43:$D$83="T1")*($M$43:$M$83)*($E13=$P$43:$P$83)) | J13: =SUMPRODUCT(($D$43:$D$83="T2")*($L$43:$L$83)*($E13>=$O$43:$O$83))-SUMPRODUCT(($D$43:$D$83="T2")*($M$43:$M$83)*($E13=$P$43:$P$83)) | K13: =SUMPRODUCT(($D$43:$D$83="T3")*($L$43:$L$83)*($E13>=$O$43:$O$83))-SUMPRODUCT(($D$43:$D$83="T3")*($M$43:$M$83)*($E13=$P$43:$P$83)) | L13: 0 | M13: =H13+I13+J13+K13+L13 | N13: =F13+M13 | O13: =O12+N13 | P13: =IF(O13<500000,"⚠ Crisis (<$500K)",IF(O13<1000000,"Caution","OK"))
B14: W29 | C14: 46222 | D14: Jul | E14: 10 | F14: -660599 | G14: 153105 | H14: ='03_Cost_Levers'!$G$16 | I14: =SUMPRODUCT(($D$43:$D$83="T1")*($L$43:$L$83)*($E14>=$O$43:$O$83))-SUMPRODUCT(($D$43:$D$83="T1")*($M$43:$M$83)*($E14=$P$43:$P$83)) | J14: =SUMPRODUCT(($D$43:$D$83="T2")*($L$43:$L$83)*($E14>=$O$43:$O$83))-SUMPRODUCT(($D$43:$D$83="T2")*($M$43:$M$83)*($E14=$P$43:$P$83)) | K14: =SUMPRODUCT(($D$43:$D$83="T3")*($L$43:$L$83)*($E14>=$O$43:$O$83))-SUMPRODUCT(($D$43:$D$83="T3")*($M$43:$M$83)*($E14=$P$43:$P$83)) | L14: 0 | M14: =H14+I14+J14+K14+L14 | N14: =F14+M14 | O14: =O13+N14 | P14: =IF(O14<500000,"⚠ Crisis (<$500K)",IF(O14<1000000,"Caution","OK"))
B15: W30 | C15: 46229 | D15: Jul | E15: 11 | F15: -41339 | G15: 111766 | H15: ='03_Cost_Levers'!$G$16 | I15: =SUMPRODUCT(($D$43:$D$83="T1")*($L$43:$L$83)*($E15>=$O$43:$O$83))-SUMPRODUCT(($D$43:$D$83="T1")*($M$43:$M$83)*($E15=$P$43:$P$83)) | J15: =SUMPRODUCT(($D$43:$D$83="T2")*($L$43:$L$83)*($E15>=$O$43:$O$83))-SUMPRODUCT(($D$43:$D$83="T2")*($M$43:$M$83)*($E15=$P$43:$P$83)) | K15: =SUMPRODUCT(($D$43:$D$83="T3")*($L$43:$L$83)*($E15>=$O$43:$O$83))-SUMPRODUCT(($D$43:$D$83="T3")*($M$43:$M$83)*($E15=$P$43:$P$83)) | L15: 0 | M15: =H15+I15+J15+K15+L15 | N15: =F15+M15 | O15: =O14+N15 | P15: ◀ TROUGH (W30)
B16: W31 | C16: 46236 | D16: Aug | E16: 12 | F16: 349424 | G16: 461190 | H16: ='03_Cost_Levers'!$G$16 | I16: =SUMPRODUCT(($D$43:$D$83="T1")*($L$43:$L$83)*($E16>=$O$43:$O$83))-SUMPRODUCT(($D$43:$D$83="T1")*($M$43:$M$83)*($E16=$P$43:$P$83)) | J16: =SUMPRODUCT(($D$43:$D$83="T2")*($L$43:$L$83)*($E16>=$O$43:$O$83))-SUMPRODUCT(($D$43:$D$83="T2")*($M$43:$M$83)*($E16=$P$43:$P$83)) | K16: =SUMPRODUCT(($D$43:$D$83="T3")*($L$43:$L$83)*($E16>=$O$43:$O$83))-SUMPRODUCT(($D$43:$D$83="T3")*($M$43:$M$83)*($E16=$P$43:$P$83)) | L16: 0 | M16: =H16+I16+J16+K16+L16 | N16: =F16+M16 | O16: =O15+N16 | P16: =IF(O16<500000,"⚠ Crisis (<$500K)",IF(O16<1000000,"Caution","OK"))
B17: W32 | C17: 46243 | D17: Aug | E17: 13 | F17: 1827963 | G17: 2289153 | H17: ='03_Cost_Levers'!$G$16 | I17: =SUMPRODUCT(($D$43:$D$83="T1")*($L$43:$L$83)*($E17>=$O$43:$O$83))-SUMPRODUCT(($D$43:$D$83="T1")*($M$43:$M$83)*($E17=$P$43:$P$83)) | J17: =SUMPRODUCT(($D$43:$D$83="T2")*($L$43:$L$83)*($E17>=$O$43:$O$83))-SUMPRODUCT(($D$43:$D$83="T2")*($M$43:$M$83)*($E17=$P$43:$P$83)) | K17: =SUMPRODUCT(($D$43:$D$83="T3")*($L$43:$L$83)*($E17>=$O$43:$O$83))-SUMPRODUCT(($D$43:$D$83="T3")*($M$43:$M$83)*($E17=$P$43:$P$83)) | L17: 0 | M17: =H17+I17+J17+K17+L17 | N17: =F17+M17 | O17: =O16+N17 | P17: =IF(O17<500000,"⚠ Crisis (<$500K)",IF(O17<1000000,"Caution","OK"))
B18: W33 | C18: 46250 | D18: Aug | E18: 14 | F18: -384367 | G18: 1904786 | H18: ='03_Cost_Levers'!$G$16 | I18: =SUMPRODUCT(($D$43:$D$83="T1")*($L$43:$L$83)*($E18>=$O$43:$O$83))-SUMPRODUCT(($D$43:$D$83="T1")*($M$43:$M$83)*($E18=$P$43:$P$83)) | J18: =SUMPRODUCT(($D$43:$D$83="T2")*($L$43:$L$83)*($E18>=$O$43:$O$83))-SUMPRODUCT(($D$43:$D$83="T2")*($M$43:$M$83)*($E18=$P$43:$P$83)) | K18: =SUMPRODUCT(($D$43:$D$83="T3")*($L$43:$L$83)*($E18>=$O$43:$O$83))-SUMPRODUCT(($D$43:$D$83="T3")*($M$43:$M$83)*($E18=$P$43:$P$83)) | L18: 0 | M18: =H18+I18+J18+K18+L18 | N18: =F18+M18 | O18: =O17+N18 | P18: =IF(O18<500000,"⚠ Crisis (<$500K)",IF(O18<1000000,"Caution","OK"))
B19: W34 | C19: 46257 | D19: Aug | E19: 15 | F19: -166451 | G19: 1738335 | H19: ='03_Cost_Levers'!$G$16 | I19: =SUMPRODUCT(($D$43:$D$83="T1")*($L$43:$L$83)*($E19>=$O$43:$O$83))-SUMPRODUCT(($D$43:$D$83="T1")*($M$43:$M$83)*($E19=$P$43:$P$83)) | J19: =SUMPRODUCT(($D$43:$D$83="T2")*($L$43:$L$83)*($E19>=$O$43:$O$83))-SUMPRODUCT(($D$43:$D$83="T2")*($M$43:$M$83)*($E19=$P$43:$P$83)) | K19: =SUMPRODUCT(($D$43:$D$83="T3")*($L$43:$L$83)*($E19>=$O$43:$O$83))-SUMPRODUCT(($D$43:$D$83="T3")*($M$43:$M$83)*($E19=$P$43:$P$83)) | L19: =('04_Bookings_Inputs'!$D$5+'04_Bookings_Inputs'!$D$6)*0.5 | M19: =H19+I19+J19+K19+L19 | N19: =F19+M19 | O19: =O18+N19 | P19: =IF(O19<500000,"⚠ Crisis (<$500K)",IF(O19<1000000,"Caution","OK"))
B20: W35 | C20: 46264 | D20: Aug | E20: 16 | F20: 363823 | G20: 2102158 | H20: ='03_Cost_Levers'!$G$16 | I20: =SUMPRODUCT(($D$43:$D$83="T1")*($L$43:$L$83)*($E20>=$O$43:$O$83))-SUMPRODUCT(($D$43:$D$83="T1")*($M$43:$M$83)*($E20=$P$43:$P$83)) | J20: =SUMPRODUCT(($D$43:$D$83="T2")*($L$43:$L$83)*($E20>=$O$43:$O$83))-SUMPRODUCT(($D$43:$D$83="T2")*($M$43:$M$83)*($E20=$P$43:$P$83)) | K20: =SUMPRODUCT(($D$43:$D$83="T3")*($L$43:$L$83)*($E20>=$O$43:$O$83))-SUMPRODUCT(($D$43:$D$83="T3")*($M$43:$M$83)*($E20=$P$43:$P$83)) | L20: =('04_Bookings_Inputs'!$D$5+'04_Bookings_Inputs'!$D$6)*0.5 | M20: =H20+I20+J20+K20+L20 | N20: =F20+M20 | O20: =O19+N20 | P20: =IF(O20<500000,"⚠ Crisis (<$500K)",IF(O20<1000000,"Caution","OK"))
B21: W36 | C21: 46271 | D21: Sep | E21: 17 | F21: 440107 | G21: 2542265 | H21: ='03_Cost_Levers'!$G$16 | I21: =SUMPRODUCT(($D$43:$D$83="T1")*($L$43:$L$83)*($E21>=$O$43:$O$83))-SUMPRODUCT(($D$43:$D$83="T1")*($M$43:$M$83)*($E21=$P$43:$P$83)) | J21: =SUMPRODUCT(($D$43:$D$83="T2")*($L$43:$L$83)*($E21>=$O$43:$O$83))-SUMPRODUCT(($D$43:$D$83="T2")*($M$43:$M$83)*($E21=$P$43:$P$83)) | K21: =SUMPRODUCT(($D$43:$D$83="T3")*($L$43:$L$83)*($E21>=$O$43:$O$83))-SUMPRODUCT(($D$43:$D$83="T3")*($M$43:$M$83)*($E21=$P$43:$P$83)) | L21: 0 | M21: =H21+I21+J21+K21+L21 | N21: =F21+M21 | O21: =O20+N21 | P21: =IF(O21<500000,"⚠ Crisis (<$500K)",IF(O21<1000000,"Caution","OK"))
B22: W37 | C22: 46278 | D22: Sep | E22: 18 | F22: 145700 | G22: 2687965 | H22: ='03_Cost_Levers'!$G$16 | I22: =SUMPRODUCT(($D$43:$D$83="T1")*($L$43:$L$83)*($E22>=$O$43:$O$83))-SUMPRODUCT(($D$43:$D$83="T1")*($M$43:$M$83)*($E22=$P$43:$P$83)) | J22: =SUMPRODUCT(($D$43:$D$83="T2")*($L$43:$L$83)*($E22>=$O$43:$O$83))-SUMPRODUCT(($D$43:$D$83="T2")*($M$43:$M$83)*($E22=$P$43:$P$83)) | K22: =SUMPRODUCT(($D$43:$D$83="T3")*($L$43:$L$83)*($E22>=$O$43:$O$83))-SUMPRODUCT(($D$43:$D$83="T3")*($M$43:$M$83)*($E22=$P$43:$P$83)) | L22: 0 | M22: =H22+I22+J22+K22+L22 | N22: =F22+M22 | O22: =O21+N22 | P22: =IF(O22<500000,"⚠ Crisis (<$500K)",IF(O22<1000000,"Caution","OK"))
B23: W38 | C23: 46285 | D23: Sep | E23: 19 | F23: -488317 | G23: 2199648 | H23: ='03_Cost_Levers'!$G$16 | I23: =SUMPRODUCT(($D$43:$D$83="T1")*($L$43:$L$83)*($E23>=$O$43:$O$83))-SUMPRODUCT(($D$43:$D$83="T1")*($M$43:$M$83)*($E23=$P$43:$P$83)) | J23: =SUMPRODUCT(($D$43:$D$83="T2")*($L$43:$L$83)*($E23>=$O$43:$O$83))-SUMPRODUCT(($D$43:$D$83="T2")*($M$43:$M$83)*($E23=$P$43:$P$83)) | K23: =SUMPRODUCT(($D$43:$D$83="T3")*($L$43:$L$83)*($E23>=$O$43:$O$83))-SUMPRODUCT(($D$43:$D$83="T3")*($M$43:$M$83)*($E23=$P$43:$P$83)) | L23: 0 | M23: =H23+I23+J23+K23+L23 | N23: =F23+M23 | O23: =O22+N23 | P23: =IF(O23<500000,"⚠ Crisis (<$500K)",IF(O23<1000000,"Caution","OK"))
B24: W39 | C24: 46292 | D24: Sep | E24: 20 | F24: 126943 | G24: 2326591 | H24: ='03_Cost_Levers'!$G$16 | I24: =SUMPRODUCT(($D$43:$D$83="T1")*($L$43:$L$83)*($E24>=$O$43:$O$83))-SUMPRODUCT(($D$43:$D$83="T1")*($M$43:$M$83)*($E24=$P$43:$P$83)) | J24: =SUMPRODUCT(($D$43:$D$83="T2")*($L$43:$L$83)*($E24>=$O$43:$O$83))-SUMPRODUCT(($D$43:$D$83="T2")*($M$43:$M$83)*($E24=$P$43:$P$83)) | K24: =SUMPRODUCT(($D$43:$D$83="T3")*($L$43:$L$83)*($E24>=$O$43:$O$83))-SUMPRODUCT(($D$43:$D$83="T3")*($M$43:$M$83)*($E24=$P$43:$P$83)) | L24: 0 | M24: =H24+I24+J24+K24+L24 | N24: =F24+M24 | O24: =O23+N24 | P24: =IF(O24<500000,"⚠ Crisis (<$500K)",IF(O24<1000000,"Caution","OK"))
B25: W40 | C25: 46299 | D25: Oct | E25: 21 | F25: 149587 | G25: 2476178 | H25: ='03_Cost_Levers'!$G$16 | I25: =SUMPRODUCT(($D$43:$D$83="T1")*($L$43:$L$83)*($E25>=$O$43:$O$83))-SUMPRODUCT(($D$43:$D$83="T1")*($M$43:$M$83)*($E25=$P$43:$P$83)) | J25: =SUMPRODUCT(($D$43:$D$83="T2")*($L$43:$L$83)*($E25>=$O$43:$O$83))-SUMPRODUCT(($D$43:$D$83="T2")*($M$43:$M$83)*($E25=$P$43:$P$83)) | K25: =SUMPRODUCT(($D$43:$D$83="T3")*($L$43:$L$83)*($E25>=$O$43:$O$83))-SUMPRODUCT(($D$43:$D$83="T3")*($M$43:$M$83)*($E25=$P$43:$P$83)) | L25: 0 | M25: =H25+I25+J25+K25+L25 | N25: =F25+M25 | O25: =O24+N25 | P25: =IF(O25<500000,"⚠ Crisis (<$500K)",IF(O25<1000000,"Caution","OK"))
B26: W41 | C26: 46306 | D26: Oct | E26: 22 | F26: 1007089 | G26: 3483267 | H26: ='03_Cost_Levers'!$G$16 | I26: =SUMPRODUCT(($D$43:$D$83="T1")*($L$43:$L$83)*($E26>=$O$43:$O$83))-SUMPRODUCT(($D$43:$D$83="T1")*($M$43:$M$83)*($E26=$P$43:$P$83)) | J26: =SUMPRODUCT(($D$43:$D$83="T2")*($L$43:$L$83)*($E26>=$O$43:$O$83))-SUMPRODUCT(($D$43:$D$83="T2")*($M$43:$M$83)*($E26=$P$43:$P$83)) | K26: =SUMPRODUCT(($D$43:$D$83="T3")*($L$43:$L$83)*($E26>=$O$43:$O$83))-SUMPRODUCT(($D$43:$D$83="T3")*($M$43:$M$83)*($E26=$P$43:$P$83)) | L26: 0 | M26: =H26+I26+J26+K26+L26 | N26: =F26+M26 | O26: =O25+N26 | P26: =IF(O26<500000,"⚠ Crisis (<$500K)",IF(O26<1000000,"Caution","OK"))
B27: W42 | C27: 46313 | D27: Oct | E27: 23 | F27: -686778 | G27: 2796489 | H27: ='03_Cost_Levers'!$G$16 | I27: =SUMPRODUCT(($D$43:$D$83="T1")*($L$43:$L$83)*($E27>=$O$43:$O$83))-SUMPRODUCT(($D$43:$D$83="T1")*($M$43:$M$83)*($E27=$P$43:$P$83)) | J27: =SUMPRODUCT(($D$43:$D$83="T2")*($L$43:$L$83)*($E27>=$O$43:$O$83))-SUMPRODUCT(($D$43:$D$83="T2")*($M$43:$M$83)*($E27=$P$43:$P$83)) | K27: =SUMPRODUCT(($D$43:$D$83="T3")*($L$43:$L$83)*($E27>=$O$43:$O$83))-SUMPRODUCT(($D$43:$D$83="T3")*($M$43:$M$83)*($E27=$P$43:$P$83)) | L27: 0 | M27: =H27+I27+J27+K27+L27 | N27: =F27+M27 | O27: =O26+N27 | P27: =IF(O27<500000,"⚠ Crisis (<$500K)",IF(O27<1000000,"Caution","OK"))
B28: W43 | C28: 46320 | D28: Oct | E28: 24 | F28: 110920 | G28: 2907409 | H28: ='03_Cost_Levers'!$G$16 | I28: =SUMPRODUCT(($D$43:$D$83="T1")*($L$43:$L$83)*($E28>=$O$43:$O$83))-SUMPRODUCT(($D$43:$D$83="T1")*($M$43:$M$83)*($E28=$P$43:$P$83)) | J28: =SUMPRODUCT(($D$43:$D$83="T2")*($L$43:$L$83)*($E28>=$O$43:$O$83))-SUMPRODUCT(($D$43:$D$83="T2")*($M$43:$M$83)*($E28=$P$43:$P$83)) | K28: =SUMPRODUCT(($D$43:$D$83="T3")*($L$43:$L$83)*($E28>=$O$43:$O$83))-SUMPRODUCT(($D$43:$D$83="T3")*($M$43:$M$83)*($E28=$P$43:$P$83)) | L28: 0 | M28: =H28+I28+J28+K28+L28 | N28: =F28+M28 | O28: =O27+N28 | P28: =IF(O28<500000,"⚠ Crisis (<$500K)",IF(O28<1000000,"Caution","OK"))
B29: W44 | C29: 46327 | D29: Nov | E29: 25 | F29: 97463 | G29: 3004872 | H29: ='03_Cost_Levers'!$G$16 | I29: =SUMPRODUCT(($D$43:$D$83="T1")*($L$43:$L$83)*($E29>=$O$43:$O$83))-SUMPRODUCT(($D$43:$D$83="T1")*($M$43:$M$83)*($E29=$P$43:$P$83)) | J29: =SUMPRODUCT(($D$43:$D$83="T2")*($L$43:$L$83)*($E29>=$O$43:$O$83))-SUMPRODUCT(($D$43:$D$83="T2")*($M$43:$M$83)*($E29=$P$43:$P$83)) | K29: =SUMPRODUCT(($D$43:$D$83="T3")*($L$43:$L$83)*($E29>=$O$43:$O$83))-SUMPRODUCT(($D$43:$D$83="T3")*($M$43:$M$83)*($E29=$P$43:$P$83)) | L29: 0 | M29: =H29+I29+J29+K29+L29 | N29: =F29+M29 | O29: =O28+N29 | P29: =IF(O29<500000,"⚠ Crisis (<$500K)",IF(O29<1000000,"Caution","OK"))
B30: W45 | C30: 46334 | D30: Nov | E30: 26 | F30: 308515 | G30: 3313387 | H30: ='03_Cost_Levers'!$G$16 | I30: =SUMPRODUCT(($D$43:$D$83="T1")*($L$43:$L$83)*($E30>=$O$43:$O$83))-SUMPRODUCT(($D$43:$D$83="T1")*($M$43:$M$83)*($E30=$P$43:$P$83)) | J30: =SUMPRODUCT(($D$43:$D$83="T2")*($L$43:$L$83)*($E30>=$O$43:$O$83))-SUMPRODUCT(($D$43:$D$83="T2")*($M$43:$M$83)*($E30=$P$43:$P$83)) | K30: =SUMPRODUCT(($D$43:$D$83="T3")*($L$43:$L$83)*($E30>=$O$43:$O$83))-SUMPRODUCT(($D$43:$D$83="T3")*($M$43:$M$83)*($E30=$P$43:$P$83)) | L30: 0 | M30: =H30+I30+J30+K30+L30 | N30: =F30+M30 | O30: =O29+N30 | P30: =IF(O30<500000,"⚠ Crisis (<$500K)",IF(O30<1000000,"Caution","OK"))
B31: W46 | C31: 46341 | D31: Nov | E31: 27 | F31: -95370 | G31: 3218017 | H31: ='03_Cost_Levers'!$G$16 | I31: =SUMPRODUCT(($D$43:$D$83="T1")*($L$43:$L$83)*($E31>=$O$43:$O$83))-SUMPRODUCT(($D$43:$D$83="T1")*($M$43:$M$83)*($E31=$P$43:$P$83)) | J31: =SUMPRODUCT(($D$43:$D$83="T2")*($L$43:$L$83)*($E31>=$O$43:$O$83))-SUMPRODUCT(($D$43:$D$83="T2")*($M$43:$M$83)*($E31=$P$43:$P$83)) | K31: =SUMPRODUCT(($D$43:$D$83="T3")*($L$43:$L$83)*($E31>=$O$43:$O$83))-SUMPRODUCT(($D$43:$D$83="T3")*($M$43:$M$83)*($E31=$P$43:$P$83)) | L31: 0 | M31: =H31+I31+J31+K31+L31 | N31: =F31+M31 | O31: =O30+N31 | P31: =IF(O31<500000,"⚠ Crisis (<$500K)",IF(O31<1000000,"Caution","OK"))
B32: W47 | C32: 46348 | D32: Nov | E32: 28 | F32: -336667 | G32: 2881350 | H32: ='03_Cost_Levers'!$G$16 | I32: =SUMPRODUCT(($D$43:$D$83="T1")*($L$43:$L$83)*($E32>=$O$43:$O$83))-SUMPRODUCT(($D$43:$D$83="T1")*($M$43:$M$83)*($E32=$P$43:$P$83)) | J32: =SUMPRODUCT(($D$43:$D$83="T2")*($L$43:$L$83)*($E32>=$O$43:$O$83))-SUMPRODUCT(($D$43:$D$83="T2")*($M$43:$M$83)*($E32=$P$43:$P$83)) | K32: =SUMPRODUCT(($D$43:$D$83="T3")*($L$43:$L$83)*($E32>=$O$43:$O$83))-SUMPRODUCT(($D$43:$D$83="T3")*($M$43:$M$83)*($E32=$P$43:$P$83)) | L32: ='04_Bookings_Inputs'!$D$7*0.5 | M32: =H32+I32+J32+K32+L32 | N32: =F32+M32 | O32: =O31+N32 | P32: =IF(O32<500000,"⚠ Crisis (<$500K)",IF(O32<1000000,"Caution","OK"))
B33: W48 | C33: 46355 | D33: Nov | E33: 29 | F33: 72813 | G33: 2954163 | H33: ='03_Cost_Levers'!$G$16 | I33: =SUMPRODUCT(($D$43:$D$83="T1")*($L$43:$L$83)*($E33>=$O$43:$O$83))-SUMPRODUCT(($D$43:$D$83="T1")*($M$43:$M$83)*($E33=$P$43:$P$83)) | J33: =SUMPRODUCT(($D$43:$D$83="T2")*($L$43:$L$83)*($E33>=$O$43:$O$83))-SUMPRODUCT(($D$43:$D$83="T2")*($M$43:$M$83)*($E33=$P$43:$P$83)) | K33: =SUMPRODUCT(($D$43:$D$83="T3")*($L$43:$L$83)*($E33>=$O$43:$O$83))-SUMPRODUCT(($D$43:$D$83="T3")*($M$43:$M$83)*($E33=$P$43:$P$83)) | L33: ='04_Bookings_Inputs'!$D$7*0.5 | M33: =H33+I33+J33+K33+L33 | N33: =F33+M33 | O33: =O32+N33 | P33: =IF(O33<500000,"⚠ Crisis (<$500K)",IF(O33<1000000,"Caution","OK"))
B34: W49 | C34: 46362 | D34: Dec | E34: 30 | F34: 259445 | G34: 3213608 | H34: ='03_Cost_Levers'!$G$16 | I34: =SUMPRODUCT(($D$43:$D$83="T1")*($L$43:$L$83)*($E34>=$O$43:$O$83))-SUMPRODUCT(($D$43:$D$83="T1")*($M$43:$M$83)*($E34=$P$43:$P$83)) | J34: =SUMPRODUCT(($D$43:$D$83="T2")*($L$43:$L$83)*($E34>=$O$43:$O$83))-SUMPRODUCT(($D$43:$D$83="T2")*($M$43:$M$83)*($E34=$P$43:$P$83)) | K34: =SUMPRODUCT(($D$43:$D$83="T3")*($L$43:$L$83)*($E34>=$O$43:$O$83))-SUMPRODUCT(($D$43:$D$83="T3")*($M$43:$M$83)*($E34=$P$43:$P$83)) | L34: 0 | M34: =H34+I34+J34+K34+L34 | N34: =F34+M34 | O34: =O33+N34 | P34: =IF(O34<500000,"⚠ Crisis (<$500K)",IF(O34<1000000,"Caution","OK"))
B35: W50 | C35: 46369 | D35: Dec | E35: 31 | F35: 45645 | G35: 3259254 | H35: ='03_Cost_Levers'!$G$16 | I35: =SUMPRODUCT(($D$43:$D$83="T1")*($L$43:$L$83)*($E35>=$O$43:$O$83))-SUMPRODUCT(($D$43:$D$83="T1")*($M$43:$M$83)*($E35=$P$43:$P$83)) | J35: =SUMPRODUCT(($D$43:$D$83="T2")*($L$43:$L$83)*($E35>=$O$43:$O$83))-SUMPRODUCT(($D$43:$D$83="T2")*($M$43:$M$83)*($E35=$P$43:$P$83)) | K35: =SUMPRODUCT(($D$43:$D$83="T3")*($L$43:$L$83)*($E35>=$O$43:$O$83))-SUMPRODUCT(($D$43:$D$83="T3")*($M$43:$M$83)*($E35=$P$43:$P$83)) | L35: 0 | M35: =H35+I35+J35+K35+L35 | N35: =F35+M35 | O35: =O34+N35 | P35: =IF(O35<500000,"⚠ Crisis (<$500K)",IF(O35<1000000,"Caution","OK"))
B36: W51 | C36: 46376 | D36: Dec | E36: 32 | F36: -442045 | G36: 2817208 | H36: ='03_Cost_Levers'!$G$16 | I36: =SUMPRODUCT(($D$43:$D$83="T1")*($L$43:$L$83)*($E36>=$O$43:$O$83))-SUMPRODUCT(($D$43:$D$83="T1")*($M$43:$M$83)*($E36=$P$43:$P$83)) | J36: =SUMPRODUCT(($D$43:$D$83="T2")*($L$43:$L$83)*($E36>=$O$43:$O$83))-SUMPRODUCT(($D$43:$D$83="T2")*($M$43:$M$83)*($E36=$P$43:$P$83)) | K36: =SUMPRODUCT(($D$43:$D$83="T3")*($L$43:$L$83)*($E36>=$O$43:$O$83))-SUMPRODUCT(($D$43:$D$83="T3")*($M$43:$M$83)*($E36=$P$43:$P$83)) | L36: 0 | M36: =H36+I36+J36+K36+L36 | N36: =F36+M36 | O36: =O35+N36 | P36: =IF(O36<500000,"⚠ Crisis (<$500K)",IF(O36<1000000,"Caution","OK"))
B37: W52 | C37: 46383 | D37: Dec | E37: 33 | F37: 66653 | G37: 2883861 | H37: ='03_Cost_Levers'!$G$16 | I37: =SUMPRODUCT(($D$43:$D$83="T1")*($L$43:$L$83)*($E37>=$O$43:$O$83))-SUMPRODUCT(($D$43:$D$83="T1")*($M$43:$M$83)*($E37=$P$43:$P$83)) | J37: =SUMPRODUCT(($D$43:$D$83="T2")*($L$43:$L$83)*($E37>=$O$43:$O$83))-SUMPRODUCT(($D$43:$D$83="T2")*($M$43:$M$83)*($E37=$P$43:$P$83)) | K37: =SUMPRODUCT(($D$43:$D$83="T3")*($L$43:$L$83)*($E37>=$O$43:$O$83))-SUMPRODUCT(($D$43:$D$83="T3")*($M$43:$M$83)*($E37=$P$43:$P$83)) | L37: 0 | M37: =H37+I37+J37+K37+L37 | N37: =F37+M37 | O37: =O36+N37 | P37: =IF(O37<500000,"⚠ Crisis (<$500K)",IF(O37<1000000,"Caution","OK"))
B38: W53 | C38: 46390 | D38: Jan | E38: 34 | F38: 1675 | G38: 2885536 | H38: ='03_Cost_Levers'!$G$16 | I38: =SUMPRODUCT(($D$43:$D$83="T1")*($L$43:$L$83)*($E38>=$O$43:$O$83))-SUMPRODUCT(($D$43:$D$83="T1")*($M$43:$M$83)*($E38=$P$43:$P$83)) | J38: =SUMPRODUCT(($D$43:$D$83="T2")*($L$43:$L$83)*($E38>=$O$43:$O$83))-SUMPRODUCT(($D$43:$D$83="T2")*($M$43:$M$83)*($E38=$P$43:$P$83)) | K38: =SUMPRODUCT(($D$43:$D$83="T3")*($L$43:$L$83)*($E38>=$O$43:$O$83))-SUMPRODUCT(($D$43:$D$83="T3")*($M$43:$M$83)*($E38=$P$43:$P$83)) | L38: ='04_Bookings_Inputs'!$D$8*0.15 | M38: =H38+I38+J38+K38+L38 | N38: =F38+M38 | O38: =O37+N38 | P38: =IF(O38<500000,"⚠ Crisis (<$500K)",IF(O38<1000000,"Caution","OK"))
B40: HELPER TABLE — PER-EMPLOYEE DERIVED VALUES (formulas pull live from 02_Severance_Inputs)
